<mujoco model="Panthera-HT_description">
  <compiler angle="radian" meshdir="../meshes/"/>

  <asset>
    <mesh name="base_link" file="base_link.STL"/>
    <mesh name="link1" file="link1.STL"/>
    <mesh name="link2" file="link2.STL"/>
    <mesh name="link3" file="link3.STL"/>
    <mesh name="link4" file="link4.STL"/>
    <mesh name="link5" file="link5.STL"/>
    <mesh name="link6" file="link6.STL"/>
  </asset>

  <worldbody>
    <geom type="mesh" contype="0" conaffinity="0" group="1" density="0" rgba="0.752941 0.752941 0.752941 1" mesh="base_link"/>
    <geom type="mesh" rgba="0.752941 0.752941 0.752941 1" mesh="base_link"/>
    <body name="link1" pos="0 0 0.0584">
      <inertial pos="0.00278873 -0.00094387 0.0249184" quat="0.692661 0.650108 0.225614 -0.216051" mass="0.281016" diaginertia="0.000421358 0.000343661 0.000213101"/>
      <joint name="joint1" pos="0 0 0" axis="0 0 1" range="-2.4 2.4" actuatorfrcrange="-21 21"/>
      <geom type="mesh" contype="0" conaffinity="0" group="1" density="0" rgba="0.752941 0.752941 0.752941 1" mesh="link1"/>
      <geom type="mesh" rgba="0.752941 0.752941 0.752941 1" mesh="link1"/>
      <body name="link2" pos="0.018199 0 0.053">
        <inertial pos="-0.129362 -0.00213339 7.183e-05" quat="0.00988446 0.706238 0.00888299 0.70785" mass="1.51651" diaginertia="0.0227212 0.0226105 0.00044695"/>
        <joint name="joint2" pos="0 0 0" axis="0 1 0" range="0 3.2" actuatorfrcrange="-36 36"/>
        <geom type="mesh" contype="0" conaffinity="0" group="1" density="0" rgba="0.752941 0.752941 0.752941 1" mesh="link2"/>
        <geom type="mesh" rgba="0.752941 0.752941 0.752941 1" mesh="link2"/>
        <body name="link3" pos="-0.26 0 0">
          <inertial pos="0.163431 -0.00164646 0.0533743" quat="-0.0903299 0.649643 -0.0759146 0.751027" mass="0.669178" diaginertia="0.00543522 0.00538336 0.00051072"/>
          <joint name="joint3" pos="0 0 0" axis="0 -1 0" range="0 4" actuatorfrcrange="-36 36"/>
          <geom type="mesh" contype="0" conaffinity="0" group="1" density="0" rgba="0.752941 0.752941 0.752941 1" mesh="link3"/>
          <geom type="mesh" rgba="0.752941 0.752941 0.752941 1" mesh="link3"/>
          <body name="link4" pos="0.23 0 0.06">
            <inertial pos="0.0524013 -0.00055249 0.0409418" quat="-0.0119308 0.442275 0.0207973 0.896559" mass="0.307805" diaginertia="0.000483913 0.000395159 0.000124278"/>
            <joint name="joint4" pos="0 0 0" axis="0 -1 0" range="-1.6 1.6" actuatorfrcrange="-21 21"/>
            <geom type="mesh" contype="0" conaffinity="0" group="1" density="0" rgba="0.752941 0.752941 0.752941 1" mesh="link4"/>
            <geom type="mesh" rgba="0.752941 0.752941 0.752941 1" mesh="link4"/>
            <body name="link5" pos="0.07 0 0.036319">
              <inertial pos="0.00303007 8.509e-05 -0.0362408" quat="0.705992 0.0034971 0.00378767 0.708201" mass="0.237111" diaginertia="5.77301e-05 4.81515e-05 3.35885e-05"/>
              <joint name="joint5" pos="0 0 0" axis="0 0 -1" range="-1.7 1.7" actuatorfrcrange="-10 10"/>
              <geom type="mesh" contype="0" conaffinity="0" group="1" density="0" rgba="0.752941 0.752941 0.752941 1" mesh="link5"/>
              <geom type="mesh" rgba="0.752941 0.752941 0.752941 1" mesh="link5"/>
              <body name="link6" pos="0.02345 0 -0.039">
                <inertial pos="0.0670463 0.00051731 1.674e-05" quat="0.514281 0.485283 -0.501747 0.498263" mass="0.30" diaginertia="0.00167615 0.00107409 0.000688931"/>
                <joint name="joint6" pos="0 0 0" axis="1 0 0" range="-2.5 2.5" actuatorfrcrange="-10 10"/>
                <geom type="mesh" contype="0" conaffinity="0" group="1" density="0" rgba="0.752941 0.752941 0.752941 1" mesh="link6"/>
                <geom type="mesh" rgba="0.752941 0.752941 0.752941 1" mesh="link6"/>
              </body>
            </body>
          </body>
        </body>
      </body>
    </body>
  </worldbody>
</mujoco>
